<?xml version="1.0" ?>
<robot name="CombinedRobot">
  <!-- Linear Axis Links -->
  <link name="base_link">
    <inertial>
      <origin xyz="0 0 0" rpy="0 0 0"/>
      <mass value="200.0"/>
      <inertia ixx="2.0" ixy="0.0" ixz="0.0" iyy="2.0" iyz="0.0" izz="2.0"/>
    </inertial>
    <collision name="collision">
      <geometry>
        <mesh filename="linear_axis/meshes/collision/base_link.obj"/>
      </geometry>
      <material name="grey">
        <color rgba="0.7 0.7 0.7 1.0"/>
      </material>
    </collision>
    <visual name="visual">
      <geometry>
        <mesh filename="linear_axis/meshes/visual/base_link.obj"/>
      </geometry>
      <material name="grey">
        <color rgba="0.7 0.7 0.7 1.0"/>
      </material>
    </visual>
  </link>
  <link name="linear_axis_link_1">
    <inertial>
      <origin xyz="0 0 0" rpy="0 0 0"/>
      <mass value="50.0"/>
      <inertia ixx="0.5" ixy="0.0" ixz="0.0" iyy="0.5" iyz="0.0" izz="0.5"/>
    </inertial>
    <collision name="collision">
      <geometry>
        <mesh filename="linear_axis/meshes/collision/link_1.obj"/>
      </geometry>
      <material name="grey">
        <color rgba="0.7 0.7 0.7 1.0"/>
      </material>
    </collision>
    <visual name="visual">
      <geometry>
        <mesh filename="linear_axis/meshes/visual/link_1.obj"/>
      </geometry>
      <material name="grey">
        <color rgba="0.7 0.7 0.7 1.0"/>
      </material>
    </visual>
  </link>

  <!-- ABB Robot Links -->
  <link name="abb_base_link">
    <inertial>
      <origin xyz="0 0 0" rpy="0 0 0"/>
      <mass value="100.0"/>
      <inertia ixx="1.0" ixy="0.0" ixz="0.0" iyy="1.0" iyz="0.0" izz="1.0"/>
    </inertial>
    <collision name="collision">
      <geometry>
        <mesh filename="abb_irb6700_150_320/meshes/collision/base_link.obj"/>
      </geometry>
      <material name="grey">
        <color rgba="0.7 0.7 0.7 1"/>
      </material>
    </collision>
    <visual name="visual">
      <geometry>
        <mesh filename="abb_irb6700_150_320/meshes/visual/base_link.obj"/>
      </geometry>
      <material name="grey">
        <color rgba="0.7 0.7 0.7 1"/>
      </material>
    </visual>
  </link>
  <link name="abb_link_1">
    <inertial>
      <origin xyz="0 0 0" rpy="0 0 0"/>
      <mass value="50.0"/>
      <inertia ixx="0.5" ixy="0.0" ixz="0.0" iyy="0.5" iyz="0.0" izz="0.5"/>
    </inertial>
    <collision name="collision">
      <geometry>
        <mesh filename="abb_irb6700_150_320/meshes/collision/link_1.obj"/>
      </geometry>
      <material name="grey">
        <color rgba="0.7 0.7 0.7 1"/>
      </material>
    </collision>
    <visual name="visual">
      <geometry>
        <mesh filename="abb_irb6700_150_320/meshes/visual/link_1.obj"/>
      </geometry>
      <material name="grey">
        <color rgba="0.7 0.7 0.7 1"/>
      </material>
    </visual>
  </link>
  <link name="abb_link_2">
    <inertial>
      <origin xyz="0 0 0" rpy="0 0 0"/>
      <mass value="40.0"/>
      <inertia ixx="0.4" ixy="0.0" ixz="0.0" iyy="0.4" iyz="0.0" izz="0.4"/>
    </inertial>
    <collision name="collision">
      <geometry>
        <mesh filename="abb_irb6700_150_320/meshes/collision/link_2.obj"/>
      </geometry>
      <material name="grey">
        <color rgba="0.7 0.7 0.7 1"/>
      </material>
    </collision>
    <visual name="visual">
      <geometry>
        <mesh filename="abb_irb6700_150_320/meshes/visual/link_2.obj"/>
      </geometry>
      <material name="grey">
        <color rgba="0.7 0.7 0.7 1"/>
      </material>
    </visual>
  </link>
  <link name="abb_link_3">
    <inertial>
      <origin xyz="0 0 0" rpy="0 0 0"/>
      <mass value="30.0"/>
      <inertia ixx="0.3" ixy="0.0" ixz="0.0" iyy="0.3" iyz="0.0" izz="0.3"/>
    </inertial>
    <collision name="collision">
      <geometry>
        <mesh filename="abb_irb6700_150_320/meshes/collision/link_3.obj"/>
      </geometry>
      <material name="grey">
        <color rgba="0.7 0.7 0.7 1"/>
      </material>
    </collision>
    <visual name="visual">
      <geometry>
        <mesh filename="abb_irb6700_150_320/meshes/visual/link_3.obj"/>
      </geometry>
      <material name="grey">
        <color rgba="0.7 0.7 0.7 1"/>
      </material>
    </visual>
  </link>
  <link name="abb_link_4">
    <inertial>
      <origin xyz="0 0 0" rpy="0 0 0"/>
      <mass value="20.0"/>
      <inertia ixx="0.2" ixy="0.0" ixz="0.0" iyy="0.2" iyz="0.0" izz="0.2"/>
    </inertial>
    <collision name="collision">
      <geometry>
        <mesh filename="abb_irb6700_150_320/meshes/collision/link_4.obj"/>
      </geometry>
      <material name="grey">
        <color rgba="0.7 0.7 0.7 1"/>
      </material>
    </collision>
    <visual name="visual">
      <geometry>
        <mesh filename="abb_irb6700_150_320/meshes/visual/link_4.obj"/>
      </geometry>
      <material name="grey">
        <color rgba="0.7 0.7 0.7 1"/>
      </material>
    </visual>
  </link>
  <link name="abb_link_5">
    <inertial>
      <origin xyz="0 0 0" rpy="0 0 0"/>
      <mass value="10.0"/>
      <inertia ixx="0.1" ixy="0.0" ixz="0.0" iyy="0.1" iyz="0.0" izz="0.1"/>
    </inertial>
    <collision name="collision">
      <geometry>
        <mesh filename="abb_irb6700_150_320/meshes/collision/link_5.obj"/>
      </geometry>
      <material name="grey">
        <color rgba="0.7 0.7 0.7 1"/>
      </material>
    </collision>
    <visual name="visual">
      <geometry>
        <mesh filename="abb_irb6700_150_320/meshes/visual/link_5.obj"/>
      </geometry>
      <material name="grey">
        <color rgba="0.7 0.7 0.7 1"/>
      </material>
    </visual>
  </link>
  <link name="abb_link_6">
    <inertial>
      <origin xyz="0 0 0" rpy="0 0 0"/>
      <mass value="5.0"/>
      <inertia ixx="0.05" ixy="0.0" ixz="0.0" iyy="0.05" iyz="0.0" izz="0.05"/>
    </inertial>
    <collision name="collision">
      <geometry>
        <mesh filename="abb_irb6700_150_320/meshes/collision/link_6.obj"/>
      </geometry>
      <material name="grey">
        <color rgba="0.3 0.3 0.3 1"/>
      </material>
    </collision>
    <visual name="visual">
      <geometry>
        <mesh filename="abb_irb6700_150_320/meshes/visual/link_6.obj"/>
      </geometry>
      <material name="grey">
        <color rgba="0.3 0.3 0.3 1"/>
      </material>
    </visual>
  </link>
  <link name="abb_flange">
    <inertial>
      <origin xyz="0 0 0" rpy="0 0 0"/>
      <mass value="1.0"/>
      <inertia ixx="0.01" ixy="0.0" ixz="0.0" iyy="0.01" iyz="0.0" izz="0.01"/>
    </inertial>
  </link>

  <!-- Joints -->
  <joint name="linear_axis_joint" type="prismatic">
    <origin rpy="0 0 0" xyz="0 0 0"/>
    <axis xyz="1 0 0"/>
    <parent link="base_link"/>
    <child link="linear_axis_link_1"/>
    <limit effort="1000" lower="-0.41" upper="7.3" velocity="1.0"/>
    <dynamics damping="0.1" friction="0.2"/>
  </joint>
  <joint name="linear_axis_to_abb" type="fixed">
    <origin rpy="0 0 0" xyz="0.6 0.43 0.55"/>
    <parent link="linear_axis_link_1"/>
    <child link="abb_base_link"/>
  </joint>
  <joint name="abb_joint_1" type="revolute">
    <origin rpy="0 0 0" xyz="0 0 0.780"/>
    <axis xyz="0 0 1"/>
    <parent link="abb_base_link"/>
    <child link="abb_link_1"/>
    <limit effort="0" lower="-2.9670597283903604" upper="2.9670597283903604" velocity="1.7453292519943295"/>
    <dynamics damping="0.05" friction="0.1"/>
  </joint>
  <joint name="abb_joint_2" type="revolute">
    <origin rpy="0 0 0" xyz="0.320 0 0"/>
    <axis xyz="0 1 0"/>
    <parent link="abb_link_1"/>
    <child link="abb_link_2"/>
    <limit effort="0" lower="-1.1344640137963142" upper="1.4835298641951802" velocity="1.5707963267948966"/>
    <dynamics damping="0.05" friction="0.1"/>
  </joint>
  <joint name="abb_joint_3" type="revolute">
    <origin rpy="0 0 0" xyz="0 0 1.280"/>
    <axis xyz="0 1 0"/>
    <parent link="abb_link_2"/>
    <child link="abb_link_3"/>
    <limit effort="0" lower="-3.141592653589793" upper="1.2217304763960306" velocity="1.5707963267948966"/>
    <dynamics damping="0.05" friction="0.1"/>
  </joint>
  <joint name="abb_joint_4" type="revolute">
    <origin rpy="0 0 0" xyz="0 0 0.200"/>
    <axis xyz="1 0 0"/>
    <parent link="abb_link_3"/>
    <child link="abb_link_4"/>
    <limit effort="0" lower="-5.235987755982989" upper="5.235987755982989" velocity="2.9670597283903604"/>
    <dynamics damping="0.05" friction="0.1"/>
  </joint>
  <joint name="abb_joint_5" type="revolute">
    <origin rpy="0 0 0" xyz="1.5925 0 0"/>
    <axis xyz="0 1 0"/>
    <parent link="abb_link_4"/>
    <child link="abb_link_5"/>
    <limit effort="0" lower="-2.2689280275926285" upper="2.2689280275926285" velocity="2.0943951023931953"/>
    <dynamics damping="0.05" friction="0.1"/>
  </joint>
  <joint name="abb_joint_6" type="revolute">
    <origin rpy="0 0 0" xyz="0.200 0 0"/>
    <axis xyz="1 0 0"/>
    <parent link="abb_link_5"/>
    <child link="abb_link_6"/>
    <limit effort="0" lower="-6.283185307179586" upper="6.283185307179586" velocity="3.3161255787892263"/>
    <dynamics damping="0.05" friction="0.1"/>
  </joint>
  <joint name="abb_joint_6-flange" type="fixed">
    <origin rpy="0 1.5707963267948966 0" xyz="0 0 0"/>
    <parent link="abb_link_6"/>
    <child link="abb_flange"/>
  </joint>
</robot>